[2022-07-30 15:45:52,761] {taskinstance.py:1032} INFO - Dependencies all met for <TaskInstance: data_ingestion_gcs_dag.local_to_gcs_task scheduled__2022-07-29T00:00:00+00:00 [queued]>
[2022-07-30 15:45:52,768] {taskinstance.py:1032} INFO - Dependencies all met for <TaskInstance: data_ingestion_gcs_dag.local_to_gcs_task scheduled__2022-07-29T00:00:00+00:00 [queued]>
[2022-07-30 15:45:52,769] {taskinstance.py:1238} INFO - 
--------------------------------------------------------------------------------
[2022-07-30 15:45:52,769] {taskinstance.py:1239} INFO - Starting attempt 1 of 2
[2022-07-30 15:45:52,769] {taskinstance.py:1240} INFO - 
--------------------------------------------------------------------------------
[2022-07-30 15:45:52,776] {taskinstance.py:1259} INFO - Executing <Task(PythonOperator): local_to_gcs_task> on 2022-07-29 00:00:00+00:00
[2022-07-30 15:45:52,783] {standard_task_runner.py:52} INFO - Started process 131 to run task
[2022-07-30 15:45:52,786] {standard_task_runner.py:76} INFO - Running: ['***', 'tasks', 'run', 'data_ingestion_gcs_dag', 'local_to_gcs_task', 'scheduled__2022-07-29T00:00:00+00:00', '--job-id', '5', '--raw', '--subdir', 'DAGS_FOLDER/data_ingestion_gcs_dag.py', '--cfg-path', '/tmp/tmpi1u4q4wv', '--error-file', '/tmp/tmpv5di1ygm']
[2022-07-30 15:45:52,786] {standard_task_runner.py:77} INFO - Job 5: Subtask local_to_gcs_task
[2022-07-30 15:45:52,847] {logging_mixin.py:109} INFO - Running <TaskInstance: data_ingestion_gcs_dag.local_to_gcs_task scheduled__2022-07-29T00:00:00+00:00 [running]> on host f758b99dedc2
[2022-07-30 15:45:52,884] {taskinstance.py:1426} INFO - Exporting the following env vars:
AIRFLOW_CTX_DAG_OWNER=***
AIRFLOW_CTX_DAG_ID=data_ingestion_gcs_dag
AIRFLOW_CTX_TASK_ID=local_to_gcs_task
AIRFLOW_CTX_EXECUTION_DATE=2022-07-29T00:00:00+00:00
AIRFLOW_CTX_DAG_RUN_ID=scheduled__2022-07-29T00:00:00+00:00
[2022-07-30 15:45:52,885] {taskinstance.py:1700} ERROR - Task failed with exception
Traceback (most recent call last):
  File "/home/airflow/.local/lib/python3.7/site-packages/airflow/models/taskinstance.py", line 1329, in _run_raw_task
    self._execute_task_with_callbacks(context)
  File "/home/airflow/.local/lib/python3.7/site-packages/airflow/models/taskinstance.py", line 1455, in _execute_task_with_callbacks
    result = self._execute_task(context, self.task)
  File "/home/airflow/.local/lib/python3.7/site-packages/airflow/models/taskinstance.py", line 1511, in _execute_task
    result = execute_callable(context=context)
  File "/home/airflow/.local/lib/python3.7/site-packages/airflow/operators/python.py", line 174, in execute
    return_value = self.execute_callable()
  File "/home/airflow/.local/lib/python3.7/site-packages/airflow/operators/python.py", line 185, in execute_callable
    return self.python_callable(*self.op_args, **self.op_kwargs)
  File "/opt/airflow/dags/data_ingestion_gcs_dag.py", line 47, in upload_to_gcs
    client = storage.Client()
  File "/home/airflow/.local/lib/python3.7/site-packages/google/cloud/storage/client.py", line 128, in __init__
    _http=_http,
  File "/home/airflow/.local/lib/python3.7/site-packages/google/cloud/client.py", line 318, in __init__
    _ClientProjectMixin.__init__(self, project=project, credentials=credentials)
  File "/home/airflow/.local/lib/python3.7/site-packages/google/cloud/client.py", line 266, in __init__
    project = self._determine_default(project)
  File "/home/airflow/.local/lib/python3.7/site-packages/google/cloud/client.py", line 285, in _determine_default
    return _determine_default_project(project)
  File "/home/airflow/.local/lib/python3.7/site-packages/google/cloud/_helpers.py", line 186, in _determine_default_project
    _, project = google.auth.default()
  File "/home/airflow/.local/lib/python3.7/site-packages/google/auth/_default.py", line 459, in default
    credentials, project_id = checker()
  File "/home/airflow/.local/lib/python3.7/site-packages/google/auth/_default.py", line 222, in _get_explicit_environ_credentials
    os.environ[environment_vars.CREDENTIALS]
  File "/home/airflow/.local/lib/python3.7/site-packages/google/auth/_default.py", line 108, in load_credentials_from_file
    "File {} was not found.".format(filename)
google.auth.exceptions.DefaultCredentialsError: File /.google/credentials/google_credentials.json was not found.
[2022-07-30 15:45:52,894] {taskinstance.py:1277} INFO - Marking task as UP_FOR_RETRY. dag_id=data_ingestion_gcs_dag, task_id=local_to_gcs_task, execution_date=20220729T000000, start_date=20220730T154552, end_date=20220730T154552
[2022-07-30 15:45:52,903] {standard_task_runner.py:92} ERROR - Failed to execute job 5 for task local_to_gcs_task
Traceback (most recent call last):
  File "/home/airflow/.local/lib/python3.7/site-packages/airflow/task/task_runner/standard_task_runner.py", line 85, in _start_by_fork
    args.func(args, dag=self.dag)
  File "/home/airflow/.local/lib/python3.7/site-packages/airflow/cli/cli_parser.py", line 48, in command
    return func(*args, **kwargs)
  File "/home/airflow/.local/lib/python3.7/site-packages/airflow/utils/cli.py", line 92, in wrapper
    return f(*args, **kwargs)
  File "/home/airflow/.local/lib/python3.7/site-packages/airflow/cli/commands/task_command.py", line 298, in task_run
    _run_task_by_selected_method(args, dag, ti)
  File "/home/airflow/.local/lib/python3.7/site-packages/airflow/cli/commands/task_command.py", line 107, in _run_task_by_selected_method
    _run_raw_task(args, ti)
  File "/home/airflow/.local/lib/python3.7/site-packages/airflow/cli/commands/task_command.py", line 184, in _run_raw_task
    error_file=args.error_file,
  File "/home/airflow/.local/lib/python3.7/site-packages/airflow/utils/session.py", line 70, in wrapper
    return func(*args, session=session, **kwargs)
  File "/home/airflow/.local/lib/python3.7/site-packages/airflow/models/taskinstance.py", line 1329, in _run_raw_task
    self._execute_task_with_callbacks(context)
  File "/home/airflow/.local/lib/python3.7/site-packages/airflow/models/taskinstance.py", line 1455, in _execute_task_with_callbacks
    result = self._execute_task(context, self.task)
  File "/home/airflow/.local/lib/python3.7/site-packages/airflow/models/taskinstance.py", line 1511, in _execute_task
    result = execute_callable(context=context)
  File "/home/airflow/.local/lib/python3.7/site-packages/airflow/operators/python.py", line 174, in execute
    return_value = self.execute_callable()
  File "/home/airflow/.local/lib/python3.7/site-packages/airflow/operators/python.py", line 185, in execute_callable
    return self.python_callable(*self.op_args, **self.op_kwargs)
  File "/opt/airflow/dags/data_ingestion_gcs_dag.py", line 47, in upload_to_gcs
    client = storage.Client()
  File "/home/airflow/.local/lib/python3.7/site-packages/google/cloud/storage/client.py", line 128, in __init__
    _http=_http,
  File "/home/airflow/.local/lib/python3.7/site-packages/google/cloud/client.py", line 318, in __init__
    _ClientProjectMixin.__init__(self, project=project, credentials=credentials)
  File "/home/airflow/.local/lib/python3.7/site-packages/google/cloud/client.py", line 266, in __init__
    project = self._determine_default(project)
  File "/home/airflow/.local/lib/python3.7/site-packages/google/cloud/client.py", line 285, in _determine_default
    return _determine_default_project(project)
  File "/home/airflow/.local/lib/python3.7/site-packages/google/cloud/_helpers.py", line 186, in _determine_default_project
    _, project = google.auth.default()
  File "/home/airflow/.local/lib/python3.7/site-packages/google/auth/_default.py", line 459, in default
    credentials, project_id = checker()
  File "/home/airflow/.local/lib/python3.7/site-packages/google/auth/_default.py", line 222, in _get_explicit_environ_credentials
    os.environ[environment_vars.CREDENTIALS]
  File "/home/airflow/.local/lib/python3.7/site-packages/google/auth/_default.py", line 108, in load_credentials_from_file
    "File {} was not found.".format(filename)
google.auth.exceptions.DefaultCredentialsError: File /.google/credentials/google_credentials.json was not found.
[2022-07-30 15:45:52,917] {local_task_job.py:154} INFO - Task exited with return code 1
[2022-07-30 15:45:52,943] {local_task_job.py:264} INFO - 0 downstream tasks scheduled from follow-on schedule check
[2022-07-30 16:12:58,293] {taskinstance.py:1032} INFO - Dependencies all met for <TaskInstance: data_ingestion_gcs_dag.local_to_gcs_task scheduled__2022-07-29T00:00:00+00:00 [queued]>
[2022-07-30 16:12:58,301] {taskinstance.py:1032} INFO - Dependencies all met for <TaskInstance: data_ingestion_gcs_dag.local_to_gcs_task scheduled__2022-07-29T00:00:00+00:00 [queued]>
[2022-07-30 16:12:58,302] {taskinstance.py:1238} INFO - 
--------------------------------------------------------------------------------
[2022-07-30 16:12:58,302] {taskinstance.py:1239} INFO - Starting attempt 1 of 2
[2022-07-30 16:12:58,302] {taskinstance.py:1240} INFO - 
--------------------------------------------------------------------------------
[2022-07-30 16:12:58,309] {taskinstance.py:1259} INFO - Executing <Task(PythonOperator): local_to_gcs_task> on 2022-07-29 00:00:00+00:00
[2022-07-30 16:12:58,316] {standard_task_runner.py:52} INFO - Started process 166 to run task
[2022-07-30 16:12:58,318] {standard_task_runner.py:76} INFO - Running: ['***', 'tasks', 'run', 'data_ingestion_gcs_dag', 'local_to_gcs_task', 'scheduled__2022-07-29T00:00:00+00:00', '--job-id', '5', '--raw', '--subdir', 'DAGS_FOLDER/data_ingestion_gcs_dag.py', '--cfg-path', '/tmp/tmp5_aq2_82', '--error-file', '/tmp/tmpkifpibn2']
[2022-07-30 16:12:58,319] {standard_task_runner.py:77} INFO - Job 5: Subtask local_to_gcs_task
[2022-07-30 16:12:58,353] {logging_mixin.py:109} INFO - Running <TaskInstance: data_ingestion_gcs_dag.local_to_gcs_task scheduled__2022-07-29T00:00:00+00:00 [running]> on host d21378671bd5
[2022-07-30 16:12:58,388] {taskinstance.py:1426} INFO - Exporting the following env vars:
AIRFLOW_CTX_DAG_OWNER=***
AIRFLOW_CTX_DAG_ID=data_ingestion_gcs_dag
AIRFLOW_CTX_TASK_ID=local_to_gcs_task
AIRFLOW_CTX_EXECUTION_DATE=2022-07-29T00:00:00+00:00
AIRFLOW_CTX_DAG_RUN_ID=scheduled__2022-07-29T00:00:00+00:00
[2022-07-30 16:12:58,523] {python.py:175} INFO - Done. Returned value was: None
[2022-07-30 16:12:58,532] {taskinstance.py:1277} INFO - Marking task as SUCCESS. dag_id=data_ingestion_gcs_dag, task_id=local_to_gcs_task, execution_date=20220729T000000, start_date=20220730T161258, end_date=20220730T161258
[2022-07-30 16:12:58,570] {local_task_job.py:154} INFO - Task exited with return code 0
[2022-07-30 16:12:58,595] {local_task_job.py:264} INFO - 1 downstream tasks scheduled from follow-on schedule check
[2022-07-30 16:27:39,537] {taskinstance.py:1032} INFO - Dependencies all met for <TaskInstance: data_ingestion_gcs_dag.local_to_gcs_task scheduled__2022-07-29T00:00:00+00:00 [queued]>
[2022-07-30 16:27:39,545] {taskinstance.py:1032} INFO - Dependencies all met for <TaskInstance: data_ingestion_gcs_dag.local_to_gcs_task scheduled__2022-07-29T00:00:00+00:00 [queued]>
[2022-07-30 16:27:39,545] {taskinstance.py:1238} INFO - 
--------------------------------------------------------------------------------
[2022-07-30 16:27:39,545] {taskinstance.py:1239} INFO - Starting attempt 1 of 2
[2022-07-30 16:27:39,546] {taskinstance.py:1240} INFO - 
--------------------------------------------------------------------------------
[2022-07-30 16:27:39,553] {taskinstance.py:1259} INFO - Executing <Task(PythonOperator): local_to_gcs_task> on 2022-07-29 00:00:00+00:00
[2022-07-30 16:27:39,559] {standard_task_runner.py:52} INFO - Started process 131 to run task
[2022-07-30 16:27:39,561] {standard_task_runner.py:76} INFO - Running: ['***', 'tasks', 'run', 'data_ingestion_gcs_dag', 'local_to_gcs_task', 'scheduled__2022-07-29T00:00:00+00:00', '--job-id', '5', '--raw', '--subdir', 'DAGS_FOLDER/data_ingestion_gcs_dag.py', '--cfg-path', '/tmp/tmp0klhz0r7', '--error-file', '/tmp/tmps97m8_6r']
[2022-07-30 16:27:39,562] {standard_task_runner.py:77} INFO - Job 5: Subtask local_to_gcs_task
[2022-07-30 16:27:39,596] {logging_mixin.py:109} INFO - Running <TaskInstance: data_ingestion_gcs_dag.local_to_gcs_task scheduled__2022-07-29T00:00:00+00:00 [running]> on host cabe1fce590a
[2022-07-30 16:27:39,634] {taskinstance.py:1426} INFO - Exporting the following env vars:
AIRFLOW_CTX_DAG_OWNER=***
AIRFLOW_CTX_DAG_ID=data_ingestion_gcs_dag
AIRFLOW_CTX_TASK_ID=local_to_gcs_task
AIRFLOW_CTX_EXECUTION_DATE=2022-07-29T00:00:00+00:00
AIRFLOW_CTX_DAG_RUN_ID=scheduled__2022-07-29T00:00:00+00:00
[2022-07-30 16:27:39,778] {python.py:175} INFO - Done. Returned value was: None
[2022-07-30 16:27:39,787] {taskinstance.py:1277} INFO - Marking task as SUCCESS. dag_id=data_ingestion_gcs_dag, task_id=local_to_gcs_task, execution_date=20220729T000000, start_date=20220730T162739, end_date=20220730T162739
[2022-07-30 16:27:39,813] {local_task_job.py:154} INFO - Task exited with return code 0
[2022-07-30 16:27:39,836] {local_task_job.py:264} INFO - 1 downstream tasks scheduled from follow-on schedule check
